Error in generate.py:
'DataGenerator' object has no attribute 'save'
Traceback (most recent call last):
  File "C:\Users\ec\Documents\Buildable-ML-DL-Fellowship\week4\synthetic_data_pipeline_project\src\generate.py", line 9, in main
    gen.save("data/raw/generated_data.csv")
    ^^^^^^^^
AttributeError: 'DataGenerator' object has no attribute 'save'


Error in train.py:
"['target'] not found in axis"
Traceback (most recent call last):
  File "C:\Users\ec\Documents\Buildable-ML-DL-Fellowship\week4\synthetic_data_pipeline_project\src\train.py", line 15, in main
    X = df.drop("target", axis=1)
  File "C:\Users\ec\Documents\Buildable-ML-DL-Fellowship\week4\synthetic_data_pipeline_project\venv\Lib\site-packages\pandas\core\frame.py", line 5588, in drop
    return super().drop(
           ~~~~~~~~~~~~^
        labels=labels,
        ^^^^^^^^^^^^^^
    ...<5 lines>...
        errors=errors,
        ^^^^^^^^^^^^^^
    )
    ^
  File "C:\Users\ec\Documents\Buildable-ML-DL-Fellowship\week4\synthetic_data_pipeline_project\venv\Lib\site-packages\pandas\core\generic.py", line 4807, in drop
    obj = obj._drop_axis(labels, axis, level=level, errors=errors)
  File "C:\Users\ec\Documents\Buildable-ML-DL-Fellowship\week4\synthetic_data_pipeline_project\venv\Lib\site-packages\pandas\core\generic.py", line 4849, in _drop_axis
    new_axis = axis.drop(labels, errors=errors)
  File "C:\Users\ec\Documents\Buildable-ML-DL-Fellowship\week4\synthetic_data_pipeline_project\venv\Lib\site-packages\pandas\core\indexes\base.py", line 7136, in drop
    raise KeyError(f"{labels[mask].tolist()} not found in axis")
KeyError: "['target'] not found in axis"


Error in generate.py:
'DataGenerator' object has no attribute 'save'
Traceback (most recent call last):
  File "C:\Users\ec\Documents\Buildable-ML-DL-Fellowship\week4\synthetic_data_pipeline_project\src\generate.py", line 9, in main
    gen.save("data/raw/generated_data.csv")
    ^^^^^^^^
AttributeError: 'DataGenerator' object has no attribute 'save'


Error in visualize_run.py:
'gender'
Traceback (most recent call last):
  File "C:\Users\ec\Documents\Buildable-ML-DL-Fellowship\week4\synthetic_data_pipeline_project\venv\Lib\site-packages\pandas\core\indexes\base.py", line 3812, in get_loc
    return self._engine.get_loc(casted_key)
           ~~~~~~~~~~~~~~~~~~~~^^^^^^^^^^^^
  File "pandas/_libs/index.pyx", line 167, in pandas._libs.index.IndexEngine.get_loc
  File "pandas/_libs/index.pyx", line 196, in pandas._libs.index.IndexEngine.get_loc
  File "pandas/_libs/hashtable_class_helper.pxi", line 7088, in pandas._libs.hashtable.PyObjectHashTable.get_item
  File "pandas/_libs/hashtable_class_helper.pxi", line 7096, in pandas._libs.hashtable.PyObjectHashTable.get_item
KeyError: 'gender'

The above exception was the direct cause of the following exception:

Traceback (most recent call last):
  File "C:\Users\ec\Documents\Buildable-ML-DL-Fellowship\week4\synthetic_data_pipeline_project\src\visualize_run.py", line 17, in main
    save_bar(
    ~~~~~~~~^
        csv_path="data/processed/augmented_data.csv",
        ^^^^^^^^^^^^^^^^^^^^^^^^^^^^^^^^^^^^^^^^^^^^^
        column="gender",
        ^^^^^^^^^^^^^^^^
        out_path="plots/bar_gender.png"
        ^^^^^^^^^^^^^^^^^^^^^^^^^^^^^^^
    )
    ^
  File "C:\Users\ec\Documents\Buildable-ML-DL-Fellowship\week4\synthetic_data_pipeline_project\synthetic_data_pipeline\visuals.py", line 32, in save_bar
    df[column].value_counts().plot(kind="bar")
    ~~^^^^^^^^
  File "C:\Users\ec\Documents\Buildable-ML-DL-Fellowship\week4\synthetic_data_pipeline_project\venv\Lib\site-packages\pandas\core\frame.py", line 4107, in __getitem__
    indexer = self.columns.get_loc(key)
  File "C:\Users\ec\Documents\Buildable-ML-DL-Fellowship\week4\synthetic_data_pipeline_project\venv\Lib\site-packages\pandas\core\indexes\base.py", line 3819, in get_loc
    raise KeyError(key) from err
KeyError: 'gender'


Error in train.py:
"['target'] not found in axis"
Traceback (most recent call last):
  File "C:\Users\ec\Documents\Buildable-ML-DL-Fellowship\week4\synthetic_data_pipeline_project\src\train.py", line 15, in main
    X = df.drop("target", axis=1)
  File "C:\Users\ec\Documents\Buildable-ML-DL-Fellowship\week4\synthetic_data_pipeline_project\venv\Lib\site-packages\pandas\core\frame.py", line 5588, in drop
    return super().drop(
           ~~~~~~~~~~~~^
        labels=labels,
        ^^^^^^^^^^^^^^
    ...<5 lines>...
        errors=errors,
        ^^^^^^^^^^^^^^
    )
    ^
  File "C:\Users\ec\Documents\Buildable-ML-DL-Fellowship\week4\synthetic_data_pipeline_project\venv\Lib\site-packages\pandas\core\generic.py", line 4807, in drop
    obj = obj._drop_axis(labels, axis, level=level, errors=errors)
  File "C:\Users\ec\Documents\Buildable-ML-DL-Fellowship\week4\synthetic_data_pipeline_project\venv\Lib\site-packages\pandas\core\generic.py", line 4849, in _drop_axis
    new_axis = axis.drop(labels, errors=errors)
  File "C:\Users\ec\Documents\Buildable-ML-DL-Fellowship\week4\synthetic_data_pipeline_project\venv\Lib\site-packages\pandas\core\indexes\base.py", line 7136, in drop
    raise KeyError(f"{labels[mask].tolist()} not found in axis")
KeyError: "['target'] not found in axis"


Error in generate.py:
'DataGenerator' object has no attribute 'save'
Traceback (most recent call last):
  File "C:\Users\ec\Documents\Buildable-ML-DL-Fellowship\week4\synthetic_data_pipeline_project\src\generate.py", line 9, in main
    gen.save("data/raw/generated_data.csv")
    ^^^^^^^^
AttributeError: 'DataGenerator' object has no attribute 'save'


Error in visualize_run.py:
'gender'
Traceback (most recent call last):
  File "C:\Users\ec\Documents\Buildable-ML-DL-Fellowship\week4\synthetic_data_pipeline_project\venv\Lib\site-packages\pandas\core\indexes\base.py", line 3812, in get_loc
    return self._engine.get_loc(casted_key)
           ~~~~~~~~~~~~~~~~~~~~^^^^^^^^^^^^
  File "pandas/_libs/index.pyx", line 167, in pandas._libs.index.IndexEngine.get_loc
  File "pandas/_libs/index.pyx", line 196, in pandas._libs.index.IndexEngine.get_loc
  File "pandas/_libs/hashtable_class_helper.pxi", line 7088, in pandas._libs.hashtable.PyObjectHashTable.get_item
  File "pandas/_libs/hashtable_class_helper.pxi", line 7096, in pandas._libs.hashtable.PyObjectHashTable.get_item
KeyError: 'gender'

The above exception was the direct cause of the following exception:

Traceback (most recent call last):
  File "C:\Users\ec\Documents\Buildable-ML-DL-Fellowship\week4\synthetic_data_pipeline_project\src\visualize_run.py", line 17, in main
    save_bar(
    ~~~~~~~~^
        csv_path="data/processed/augmented_data.csv",
        ^^^^^^^^^^^^^^^^^^^^^^^^^^^^^^^^^^^^^^^^^^^^^
        column="gender",
        ^^^^^^^^^^^^^^^^
        out_path="plots/bar_gender.png"
        ^^^^^^^^^^^^^^^^^^^^^^^^^^^^^^^
    )
    ^
  File "C:\Users\ec\Documents\Buildable-ML-DL-Fellowship\week4\synthetic_data_pipeline_project\synthetic_data_pipeline\visuals.py", line 31, in save_bar
    df[column].value_counts().plot(kind="bar")
    ~~^^^^^^^^
  File "C:\Users\ec\Documents\Buildable-ML-DL-Fellowship\week4\synthetic_data_pipeline_project\venv\Lib\site-packages\pandas\core\frame.py", line 4107, in __getitem__
    indexer = self.columns.get_loc(key)
  File "C:\Users\ec\Documents\Buildable-ML-DL-Fellowship\week4\synthetic_data_pipeline_project\venv\Lib\site-packages\pandas\core\indexes\base.py", line 3819, in get_loc
    raise KeyError(key) from err
KeyError: 'gender'


Error in train.py:
"['target'] not found in axis"
Traceback (most recent call last):
  File "C:\Users\ec\Documents\Buildable-ML-DL-Fellowship\week4\synthetic_data_pipeline_project\src\train.py", line 15, in main
    X = df.drop("target", axis=1)
  File "C:\Users\ec\Documents\Buildable-ML-DL-Fellowship\week4\synthetic_data_pipeline_project\venv\Lib\site-packages\pandas\core\frame.py", line 5588, in drop
    return super().drop(
           ~~~~~~~~~~~~^
        labels=labels,
        ^^^^^^^^^^^^^^
    ...<5 lines>...
        errors=errors,
        ^^^^^^^^^^^^^^
    )
    ^
  File "C:\Users\ec\Documents\Buildable-ML-DL-Fellowship\week4\synthetic_data_pipeline_project\venv\Lib\site-packages\pandas\core\generic.py", line 4807, in drop
    obj = obj._drop_axis(labels, axis, level=level, errors=errors)
  File "C:\Users\ec\Documents\Buildable-ML-DL-Fellowship\week4\synthetic_data_pipeline_project\venv\Lib\site-packages\pandas\core\generic.py", line 4849, in _drop_axis
    new_axis = axis.drop(labels, errors=errors)
  File "C:\Users\ec\Documents\Buildable-ML-DL-Fellowship\week4\synthetic_data_pipeline_project\venv\Lib\site-packages\pandas\core\indexes\base.py", line 7136, in drop
    raise KeyError(f"{labels[mask].tolist()} not found in axis")
KeyError: "['target'] not found in axis"


Error in generate.py:
'DataGenerator' object has no attribute 'save'
Traceback (most recent call last):
  File "C:\Users\ec\Documents\Buildable-ML-DL-Fellowship\week4\synthetic_data_pipeline_project\src\generate.py", line 9, in main
    gen.save("data/raw/generated_data.csv")
    ^^^^^^^^
AttributeError: 'DataGenerator' object has no attribute 'save'


Error in visualize_run.py:
save_hist() got an unexpected keyword argument 'csv_path'. Did you mean 'out_path'?
Traceback (most recent call last):
  File "C:\Users\ec\Documents\Buildable-ML-DL-Fellowship\week4\synthetic_data_pipeline_project\src\visualize_run.py", line 8, in main
    save_hist(
    ~~~~~~~~~^
        csv_path="data/processed/augmented_data.csv",
        ^^^^^^^^^^^^^^^^^^^^^^^^^^^^^^^^^^^^^^^^^^^^^
        column="age",
        ^^^^^^^^^^^^^
        out_path="plots/histogram_age.png"
        ^^^^^^^^^^^^^^^^^^^^^^^^^^^^^^^^^^
    )
    ^
TypeError: save_hist() got an unexpected keyword argument 'csv_path'. Did you mean 'out_path'?


Error in train.py:
"['target'] not found in axis"
Traceback (most recent call last):
  File "C:\Users\ec\Documents\Buildable-ML-DL-Fellowship\week4\synthetic_data_pipeline_project\src\train.py", line 15, in main
    X = df.drop("target", axis=1)
  File "C:\Users\ec\Documents\Buildable-ML-DL-Fellowship\week4\synthetic_data_pipeline_project\venv\Lib\site-packages\pandas\core\frame.py", line 5588, in drop
    return super().drop(
           ~~~~~~~~~~~~^
        labels=labels,
        ^^^^^^^^^^^^^^
    ...<5 lines>...
        errors=errors,
        ^^^^^^^^^^^^^^
    )
    ^
  File "C:\Users\ec\Documents\Buildable-ML-DL-Fellowship\week4\synthetic_data_pipeline_project\venv\Lib\site-packages\pandas\core\generic.py", line 4807, in drop
    obj = obj._drop_axis(labels, axis, level=level, errors=errors)
  File "C:\Users\ec\Documents\Buildable-ML-DL-Fellowship\week4\synthetic_data_pipeline_project\venv\Lib\site-packages\pandas\core\generic.py", line 4849, in _drop_axis
    new_axis = axis.drop(labels, errors=errors)
  File "C:\Users\ec\Documents\Buildable-ML-DL-Fellowship\week4\synthetic_data_pipeline_project\venv\Lib\site-packages\pandas\core\indexes\base.py", line 7136, in drop
    raise KeyError(f"{labels[mask].tolist()} not found in axis")
KeyError: "['target'] not found in axis"


Error in generate.py:
'DataGenerator' object has no attribute 'save'
Traceback (most recent call last):
  File "C:\Users\ec\Documents\Buildable-ML-DL-Fellowship\week4\synthetic_data_pipeline_project\src\generate.py", line 9, in main
    gen.save("data/raw/generated_data.csv")
    ^^^^^^^^
AttributeError: 'DataGenerator' object has no attribute 'save'


Error in generate.py:
'DataGenerator' object has no attribute 'save'
Traceback (most recent call last):
  File "C:\Users\ec\Documents\Buildable-ML-DL-Fellowship\week4\synthetic_data_pipeline_project\src\generate.py", line 9, in main
    gen.save("data/raw/generated_data.csv")
    ^^^^^^^^
AttributeError: 'DataGenerator' object has no attribute 'save'


Error in src/train.py:
could not convert string to float: 'Female'
Traceback (most recent call last):
  File "C:\Users\ec\Documents\Buildable-ML-DL-Fellowship\week4\synthetic_data_pipeline_project\src\train.py", line 25, in main
    results = trainer.train_and_evaluate()
  File "C:\Users\ec\Documents\Buildable-ML-DL-Fellowship\week4\synthetic_data_pipeline_project\synthetic_data_pipeline\trainer.py", line 21, in train_and_evaluate
    model.fit(self.X_train, self.y_train)
    ~~~~~~~~~^^^^^^^^^^^^^^^^^^^^^^^^^^^^
  File "C:\Users\ec\Documents\Buildable-ML-DL-Fellowship\week4\synthetic_data_pipeline_project\venv\Lib\site-packages\sklearn\base.py", line 1365, in wrapper
    return fit_method(estimator, *args, **kwargs)
  File "C:\Users\ec\Documents\Buildable-ML-DL-Fellowship\week4\synthetic_data_pipeline_project\venv\Lib\site-packages\sklearn\linear_model\_logistic.py", line 1247, in fit
    X, y = validate_data(
           ~~~~~~~~~~~~~^
        self,
        ^^^^^
    ...<5 lines>...
        accept_large_sparse=solver not in ["liblinear", "sag", "saga"],
        ^^^^^^^^^^^^^^^^^^^^^^^^^^^^^^^^^^^^^^^^^^^^^^^^^^^^^^^^^^^^^^^
    )
    ^
  File "C:\Users\ec\Documents\Buildable-ML-DL-Fellowship\week4\synthetic_data_pipeline_project\venv\Lib\site-packages\sklearn\utils\validation.py", line 2971, in validate_data
    X, y = check_X_y(X, y, **check_params)
           ~~~~~~~~~^^^^^^^^^^^^^^^^^^^^^^
  File "C:\Users\ec\Documents\Buildable-ML-DL-Fellowship\week4\synthetic_data_pipeline_project\venv\Lib\site-packages\sklearn\utils\validation.py", line 1368, in check_X_y
    X = check_array(
        X,
    ...<12 lines>...
        input_name="X",
    )
  File "C:\Users\ec\Documents\Buildable-ML-DL-Fellowship\week4\synthetic_data_pipeline_project\venv\Lib\site-packages\sklearn\utils\validation.py", line 971, in check_array
    array = array.astype(new_dtype)
  File "C:\Users\ec\Documents\Buildable-ML-DL-Fellowship\week4\synthetic_data_pipeline_project\venv\Lib\site-packages\pandas\core\generic.py", line 6662, in astype
    new_data = self._mgr.astype(dtype=dtype, copy=copy, errors=errors)
  File "C:\Users\ec\Documents\Buildable-ML-DL-Fellowship\week4\synthetic_data_pipeline_project\venv\Lib\site-packages\pandas\core\internals\managers.py", line 430, in astype
    return self.apply(
           ~~~~~~~~~~^
        "astype",
        ^^^^^^^^^
    ...<3 lines>...
        using_cow=using_copy_on_write(),
        ^^^^^^^^^^^^^^^^^^^^^^^^^^^^^^^^
    )
    ^
  File "C:\Users\ec\Documents\Buildable-ML-DL-Fellowship\week4\synthetic_data_pipeline_project\venv\Lib\site-packages\pandas\core\internals\managers.py", line 363, in apply
    applied = getattr(b, f)(**kwargs)
  File "C:\Users\ec\Documents\Buildable-ML-DL-Fellowship\week4\synthetic_data_pipeline_project\venv\Lib\site-packages\pandas\core\internals\blocks.py", line 784, in astype
    new_values = astype_array_safe(values, dtype, copy=copy, errors=errors)
  File "C:\Users\ec\Documents\Buildable-ML-DL-Fellowship\week4\synthetic_data_pipeline_project\venv\Lib\site-packages\pandas\core\dtypes\astype.py", line 237, in astype_array_safe
    new_values = astype_array(values, dtype, copy=copy)
  File "C:\Users\ec\Documents\Buildable-ML-DL-Fellowship\week4\synthetic_data_pipeline_project\venv\Lib\site-packages\pandas\core\dtypes\astype.py", line 182, in astype_array
    values = _astype_nansafe(values, dtype, copy=copy)
  File "C:\Users\ec\Documents\Buildable-ML-DL-Fellowship\week4\synthetic_data_pipeline_project\venv\Lib\site-packages\pandas\core\dtypes\astype.py", line 133, in _astype_nansafe
    return arr.astype(dtype, copy=True)
           ~~~~~~~~~~^^^^^^^^^^^^^^^^^^
ValueError: could not convert string to float: 'Female'

Error in train.py:
could not convert string to float: 'Female'
Traceback (most recent call last):
  File "C:\Users\ec\Documents\Buildable-ML-DL-Fellowship\week4\synthetic_data_pipeline_project\src\train.py", line 32, in main
    results["LogisticRegression"] = trainer_lr.train_and_evaluate()
                                    ~~~~~~~~~~~~~~~~~~~~~~~~~~~~~^^
  File "C:\Users\ec\Documents\Buildable-ML-DL-Fellowship\week4\synthetic_data_pipeline_project\synthetic_data_pipeline\trainer.py", line 17, in train_and_evaluate
    self.model.fit(self.X_train, self.y_train)
    ~~~~~~~~~~~~~~^^^^^^^^^^^^^^^^^^^^^^^^^^^^
  File "C:\Users\ec\Documents\Buildable-ML-DL-Fellowship\week4\synthetic_data_pipeline_project\venv\Lib\site-packages\sklearn\base.py", line 1365, in wrapper
    return fit_method(estimator, *args, **kwargs)
  File "C:\Users\ec\Documents\Buildable-ML-DL-Fellowship\week4\synthetic_data_pipeline_project\venv\Lib\site-packages\sklearn\linear_model\_logistic.py", line 1247, in fit
    X, y = validate_data(
           ~~~~~~~~~~~~~^
        self,
        ^^^^^
    ...<5 lines>...
        accept_large_sparse=solver not in ["liblinear", "sag", "saga"],
        ^^^^^^^^^^^^^^^^^^^^^^^^^^^^^^^^^^^^^^^^^^^^^^^^^^^^^^^^^^^^^^^
    )
    ^
  File "C:\Users\ec\Documents\Buildable-ML-DL-Fellowship\week4\synthetic_data_pipeline_project\venv\Lib\site-packages\sklearn\utils\validation.py", line 2971, in validate_data
    X, y = check_X_y(X, y, **check_params)
           ~~~~~~~~~^^^^^^^^^^^^^^^^^^^^^^
  File "C:\Users\ec\Documents\Buildable-ML-DL-Fellowship\week4\synthetic_data_pipeline_project\venv\Lib\site-packages\sklearn\utils\validation.py", line 1368, in check_X_y
    X = check_array(
        X,
    ...<12 lines>...
        input_name="X",
    )
  File "C:\Users\ec\Documents\Buildable-ML-DL-Fellowship\week4\synthetic_data_pipeline_project\venv\Lib\site-packages\sklearn\utils\validation.py", line 971, in check_array
    array = array.astype(new_dtype)
  File "C:\Users\ec\Documents\Buildable-ML-DL-Fellowship\week4\synthetic_data_pipeline_project\venv\Lib\site-packages\pandas\core\generic.py", line 6662, in astype
    new_data = self._mgr.astype(dtype=dtype, copy=copy, errors=errors)
  File "C:\Users\ec\Documents\Buildable-ML-DL-Fellowship\week4\synthetic_data_pipeline_project\venv\Lib\site-packages\pandas\core\internals\managers.py", line 430, in astype
    return self.apply(
           ~~~~~~~~~~^
        "astype",
        ^^^^^^^^^
    ...<3 lines>...
        using_cow=using_copy_on_write(),
        ^^^^^^^^^^^^^^^^^^^^^^^^^^^^^^^^
    )
    ^
  File "C:\Users\ec\Documents\Buildable-ML-DL-Fellowship\week4\synthetic_data_pipeline_project\venv\Lib\site-packages\pandas\core\internals\managers.py", line 363, in apply
    applied = getattr(b, f)(**kwargs)
  File "C:\Users\ec\Documents\Buildable-ML-DL-Fellowship\week4\synthetic_data_pipeline_project\venv\Lib\site-packages\pandas\core\internals\blocks.py", line 784, in astype
    new_values = astype_array_safe(values, dtype, copy=copy, errors=errors)
  File "C:\Users\ec\Documents\Buildable-ML-DL-Fellowship\week4\synthetic_data_pipeline_project\venv\Lib\site-packages\pandas\core\dtypes\astype.py", line 237, in astype_array_safe
    new_values = astype_array(values, dtype, copy=copy)
  File "C:\Users\ec\Documents\Buildable-ML-DL-Fellowship\week4\synthetic_data_pipeline_project\venv\Lib\site-packages\pandas\core\dtypes\astype.py", line 182, in astype_array
    values = _astype_nansafe(values, dtype, copy=copy)
  File "C:\Users\ec\Documents\Buildable-ML-DL-Fellowship\week4\synthetic_data_pipeline_project\venv\Lib\site-packages\pandas\core\dtypes\astype.py", line 133, in _astype_nansafe
    return arr.astype(dtype, copy=True)
           ~~~~~~~~~~^^^^^^^^^^^^^^^^^^
ValueError: could not convert string to float: 'Female'


